Workbook

Sheet Cover
B2: Super Micro Forensic Analysis: Earnings Quality and Accounting Red Flags
B3: Forensic screen · Prepared by Alessandro Radice · Educational project, not investment advice · June 2025
B6: Question | C6: On 30 June 2025, after Super Micro filed its delayed fiscal 2024 10-K (clean opinion on the numbers, adverse on internal controls): do the financial statements carry red flags, would a systematic screen have seen trouble before the August 2024 short report, and how reliable is such a screen?
B7: Inputs | C7: Choose any quarter (yellow cell). The trailing-twelve-month financials for that quarter, the year before and two years before are pulled from the Timeline sheet. Thresholds are switches too.
B8: Beneish | C8: The eight Beneish (1999) indices and the M-score for the chosen quarter, with each index's contribution from a neutral company.
B9: Dechow | C9: The Dechow, Ge, Larson and Sloan (2011) F-score, model 1, for the chosen quarter, with RSST accruals.
B10: Timeline | C10: Every quarter from June 2013 to March 2025, with the financials as first filed (SEC XBRL, point in time) and every score recomputed by formula.
B11: Validation | C11: 16 companies the SEC charged or that restated inflated earnings. Each misstated year as first filed, scored by formula; hit rates at the thresholds on Inputs.
B12: Universe | C12: M-score and F-score for 1,235 US operating companies (2023 against 2022, SEC frames API), used for false-alarm rates and percentiles.
B13: Market | C13: Daily closes of Super Micro and the Nasdaq-100 (QQQ), split-adjusted; beta and abnormal returns on the event days by formula.
B14: Checks | C14: Reconciliation of this workbook with the Python engine (Super_Micro_Forensic_Analysis.ipynb).
B15: Units | C15: Financial items in $ millions. Missing XBRL items show "n/a": the formulas then set that index to neutral (1 for Beneish indices, 0 for F-score inputs), as the Python engine does.
B16: Colour code | C16: Blue = hard-coded input · Black = formula · Green = link to another sheet · Yellow fill = switch · Red fill = flag.
B17: Sources | C17: SEC EDGAR XBRL company facts, frames and submissions APIs; DoltHub post-no-preference/stocks; SEC press releases and orders for the validation cases. Beneish (1999); Dechow et al. (2011); Richardson et al. (2005).

Sheet Inputs
B2: Inputs
B3: Switches, model coefficients and the financials of the selected quarter ($ millions)
B5: Switches
B6: Quarter end to analyse | C6: 45382 | F6: Any quarter end on the Timeline sheet. 31 Mar 2024 = the 10-Q of 6 May 2024, before the short report
B7: M-score threshold | C7: -1.78 | F7: Beneish (1999); −2.22 is a common stricter screen
B8: F-score threshold | C8: 1.85 | F8: Dechow et al. (2011): above 1 elevated, above 1.85 substantial, above 2.45 high risk
B9: Row on the Timeline sheet | C9: =MATCH(C6,Timeline!$B$6:$B$50,0)+5 -> 46 | F9: Looked up from the date above
B10: Filed | C10: =INDEX(Timeline!C:C,C9) -> 45418
B12: Beneish M-score coefficients | C12: Value | F12: Source
B13: Intercept | C13: -4.84 | F13: Beneish (1999), Financial Analysts Journal 55(5), unweighted probit
B14: DSRI · Days sales in receivables index | C14: 0.92
B15: GMI · Gross margin index | C15: 0.528
B16: AQI · Asset quality index | C16: 0.404
B17: SGI · Sales growth index | C17: 0.892
B18: DEPI · Depreciation index | C18: 0.115
B19: SGAI · SG&A index | C19: -0.172
B20: TATA · Total accruals to total assets | C20: 4.679
B21: LVGI · Leverage index | C21: -0.327
B23: Dechow F-score coefficients (model 1) | C23: Value | F23: Source
B24: Intercept | C24: -7.893 | F24: Dechow, Ge, Larson and Sloan (2011), Contemporary Accounting Research 28(1)
B25: RSST accruals | C25: 0.79
B26: Change in receivables | C26: 2.518
B27: Change in inventory | C27: 1.191
B28: Soft assets | C28: 1.979
B29: Change in cash sales | C29: 0.171
B30: Change in ROA | C30: -0.932
B31: Securities issued (0/1) | C31: 1.029
B32: Unconditional misstatement probability | C32: 0.0037
B34: Selected quarter, trailing twelve months ($M) | C34: This year (t) | D34: Year before (t−1) | E34: Two years before (t−2) | F34: Note
B35: Sales | C35: =INDEX(Timeline!AD:AD,$C$9) -> 11819.523 | D35: =INDEX(Timeline!AW:AW,$C$9) -> 6574.081 | E35: =INDEX(Timeline!BQ:BQ,$C$9) -> 4629.624 | F35: Flows are trailing twelve months; balances at the quarter end
B36: Cost of sales | C36: =INDEX(Timeline!AE:AE,$C$9) -> 9932.446 | D36: =INDEX(Timeline!AX:AX,$C$9) -> 5375.421
B37: SG&A | C37: =INDEX(Timeline!AF:AF,$C$9) -> 317.155 | D37: =INDEX(Timeline!AY:AY,$C$9) -> 205.812
B38: Depreciation | C38: =INDEX(Timeline!AG:AG,$C$9) -> 38.146 | D38: =INDEX(Timeline!AZ:AZ,$C$9) -> 34.354
B39: Net income | C39: =INDEX(Timeline!AH:AH,$C$9) -> 1048.991 | D39: =INDEX(Timeline!BA:BA,$C$9) -> 587.251 | E39: =INDEX(Timeline!BS:BS,$C$9) -> 183.503
B40: Operating cash flow | C40: =INDEX(Timeline!AI:AI,$C$9) -> -1853.497 | D40: =INDEX(Timeline!BB:BB,$C$9) -> 647.776
B41: Debt/equity issued | C41: =INDEX(Timeline!AJ:AJ,$C$9) -> 2748.384 | D41: =INDEX(Timeline!BC:BC,$C$9) -> 379.568 | F41: Proceeds from debt or equity issued in the period (F-score issuance dummy)
B42: Receivables | C42: =INDEX(Timeline!AK:AK,$C$9) -> 1650.153 | D42: =INDEX(Timeline!BD:BD,$C$9) -> 672.055 | E42: =INDEX(Timeline!BP:BP,$C$9) -> 679.785
B43: Inventory | C43: =INDEX(Timeline!AL:AL,$C$9) -> 4124.587 | D43: =INDEX(Timeline!BE:BE,$C$9) -> 1540.419
B44: Current assets | C44: =INDEX(Timeline!AM:AM,$C$9) -> 8063.932 | D44: =INDEX(Timeline!BF:BF,$C$9) -> 2715.175
B45: Total assets | C45: =INDEX(Timeline!AN:AN,$C$9) -> 8862.781 | D45: =INDEX(Timeline!BG:BG,$C$9) -> 3192.604 | E45: =INDEX(Timeline!BR:BR,$C$9) -> 3071.177
...

Sheet Beneish
B2: Beneish M-score
B3: Selected quarter on Inputs!C6 · each index against the year before · contribution = coefficient × (index − neutral)
B5: Quarter end | C5: =Inputs!C6 -> 45382
B6: Filed | C6: =Inputs!C10 -> 45418
B8: Index | C8: Value | D8: Coefficient | E8: Neutral | F8: Contribution | G8: What a high value means
B9: DSRI · Days sales in receivables index | C9: =IFERROR((Inputs!$C$42/Inputs!$C$35)/(Inputs!$D$42/Inputs!$D$35),1) -> 1.3656974 | D9: =Inputs!$C$14 -> 0.92 | E9: 1 | F9: =D9*(C9-E9) -> 0.33644165 | G9: Receivables growing faster than sales
B10: GMI · Gross margin index | C10: =IFERROR(((Inputs!$D$35-Inputs!$D$36)/Inputs!$D$35)/((Inputs!$C$35-Inputs!$C$36)/Inputs!$C$35),1) -> 1.1420136 | D10: =Inputs!$C$15 -> 0.528 | E10: 1 | F10: =D10*(C10-E10) -> 0.074983202 | G10: Gross margin shrinking
B11: AQI · Asset quality index | C11: =IFERROR((1-(Inputs!$C$44+Inputs!$C$46)/Inputs!$C$45)/(1-(Inputs!$D$44+Inputs!$D$46)/Inputs!$D$45),1) -> 0.79446331 | D11: =Inputs!$C$16 -> 0.404 | E11: 1 | F11: =D11*(C11-E11) -> -0.083036821 | G11: More costs capitalised as intangible or other assets
B12: SGI · Sales growth index | C12: =IFERROR(Inputs!$C$35/Inputs!$D$35,1) -> 1.7978974 | D12: =Inputs!$C$17 -> 0.892 | E12: 1 | F12: =D12*(C12-E12) -> 0.71172446 | G12: Fast growth, which raises pressure and opportunity
B13: DEPI · Depreciation index | C13: =IFERROR((Inputs!$D$38/(Inputs!$D$38+Inputs!$D$46))/(Inputs!$C$38/(Inputs!$C$38+Inputs!$C$46)),1) -> 1.1763294 | D13: =Inputs!$C$18 -> 0.115 | E13: 1 | F13: =D13*(C13-E13) -> 0.020277876 | G13: Depreciating more slowly
B14: SGAI · SG&A index | C14: =IFERROR((Inputs!$C$37/Inputs!$C$35)/(Inputs!$D$37/Inputs!$D$35),1) -> 0.85710883 | D14: =Inputs!$C$19 -> -0.172 | E14: 1 | F14: =D14*(C14-E14) -> 0.024577281 | G14: Overheads growing faster than sales (negative weight)
B15: TATA · Total accruals to total assets | C15: =IFERROR((Inputs!$C$39-Inputs!$C$40)/Inputs!$C$45,0) -> 0.32749179 | D15: =Inputs!$C$20 -> 4.679 | E15: 0 | F15: =D15*(C15-E15) -> 1.5323341 | G15: Profit not backed by operating cash flow
B16: LVGI · Leverage index | C16: =IFERROR(((Inputs!$C$50+N(Inputs!$C$52))/Inputs!$C$45)/((Inputs!$D$50+N(Inputs!$D$52))/Inputs!$D$45),1) -> 0.53002801 | D16: =Inputs!$C$21 -> -0.327 | E16: 1 | F16: =D16*(C16-E16) -> 0.15368084 | G16: More leverage (negative weight in the model)
B18: Neutral company (all indices at 1, no accruals) | F18: =Inputs!$C$13+SUMPRODUCT(D9:D16,E9:E16) -> -2.48
B19: M-score | F19: =Inputs!$C$13+SUMPRODUCT(D9:D16,C9:C16) -> 0.29098257
B20: Check: neutral + contributions | F20: =F18+SUM(F9:F16)-F19 -> 0
B21: Flag (above the threshold on Inputs) | F21: =IF(F19>Inputs!C7,"RED FLAG","below threshold") -> RED FLAG
B22: Same quarter on the Timeline sheet | F22: =INDEX(Timeline!E:E,Inputs!C9) -> 0.29098257
B24: Beneish (1999) estimated the model on 74 manipulators and 2,332 controls (1982 to 1992). Above −1.78 a company looks more like the manipulators; the threshold is a convention, not a probability.

Sheet Dechow
B2: Dechow F-score
B3: Selected quarter on Inputs!C6 · model 1 of Dechow, Ge, Larson and Sloan (2011)
B5: Quarter end | C5: =Inputs!C6 -> 45382
B7: Variable | C7: Value | D7: Coefficient | E7: Contribution | F7: Definition
B8: RSST accruals | C8: =IFERROR((((Inputs!$C$44-Inputs!$C$47-N(Inputs!$C$48))-(Inputs!$C$50-N(Inputs!$C$53))+(Inputs!$C$45-Inputs!$C$44-N(Inputs!$C$49))-(Inputs!$C$51-Inputs!$C$50-N(Inputs!$C$52))+(N(Inputs!$C$48)+N(Inputs!$C$49))-(N(Inputs!$C$52)+N(Inputs!$C$53)))-((Inputs!$D$44-Inputs!$D$47-N(Inputs!$D$48))-(Inputs!$D$50-N(Inputs!$D$53))+(Inputs!$D$45-Inputs!$D$44-N(Inputs!$D$49))-(Inputs!$D$51-Inputs!$D$50-N(Inputs!$D$52))+(N(Inputs!$D$48)+N(Inputs!$D$49))-(N(Inputs!$D$52)+N(Inputs!$D$53))))/((Inputs!$C$45+Inputs!$D$45)/2),0) -> 0.26094695 | D8: =Inputs!$C$25 -> 0.79 | E8: =C8*D8 -> 0.20614809 | F8: Change in (working capital + net non-current operating assets + net financial assets), over average total assets (Richardson et al., 2005)
B9: Change in receivables | C9: =IFERROR((Inputs!$C$42-Inputs!$D$42)/((Inputs!$C$45+Inputs!$D$45)/2),0) -> 0.1622674 | D9: =Inputs!$C$26 -> 2.518 | E9: =C9*D9 -> 0.40858932 | F9: Change in receivables over average total assets
B10: Change in inventory | C10: =IFERROR((N(Inputs!$C$43)-N(Inputs!$D$43))/((Inputs!$C$45+Inputs!$D$45)/2),0) -> 0.42871596 | D10: =Inputs!$C$27 -> 1.191 | E10: =C10*D10 -> 0.51060071 | F10: Change in inventory over average total assets
B11: Soft assets | C11: =IFERROR((Inputs!$C$45-N(Inputs!$C$46)-Inputs!$C$47)/Inputs!$C$45,0) -> 0.71780393 | D11: =Inputs!$C$28 -> 1.979 | E11: =C11*D11 -> 1.420534 | F11: (Total assets − net PP&E − cash) / total assets
B12: Change in cash sales | C12: =IF(COUNT(Inputs!$E$42,Inputs!$E$35,Inputs!$E$45,Inputs!$E$39)=4,IFERROR((Inputs!$C$35-(Inputs!$C$42-Inputs!$D$42))/(Inputs!$D$35-(Inputs!$D$42-Inputs!$E$42))-1,0),0) -> 0.64717963 | D12: =Inputs!$C$29 -> 0.171 | E12: =C12*D12 -> 0.11066772 | F12: Growth in cash sales (sales minus the change in receivables)
B13: Change in ROA | C13: =IF(COUNT(Inputs!$E$42,Inputs!$E$35,Inputs!$E$45,Inputs!$E$39)=4,IFERROR(Inputs!$C$39/((Inputs!$C$45+Inputs!$D$45)/2)-Inputs!$D$39/((Inputs!$D$45+Inputs!$E$45)/2),0),0) -> -0.013478256 | D13: =Inputs!$C$30 -> -0.932 | E13: =C13*D13 -> 0.012561735 | F13: Change in return on average assets
B14: Securities issued (0/1) | C14: =IF(N(Inputs!$C$41)>0,1,0) -> 1 | D14: =Inputs!$C$31 -> 1.029 | E14: =C14*D14 -> 1.029 | F14: 1 if debt or equity was issued in the period
B16: Intercept | E16: =Inputs!$C$24 -> -7.893
B17: Predicted value (logit) | E17: =SUM(E8:E14)+E16 -> -4.1948985
B18: Probability of misstatement | E18: =EXP(E17)/(1+EXP(E17)) -> 0.014848473
B19: F-score (probability / 0.37% base rate) | E19: =E18/Inputs!$C$32 -> 4.0131007
B20: Risk band | E20: =IF(E19>2.45,"high",IF(E19>1.85,"substantial",IF(E19>1,"above normal","normal"))) -> high
B21: Same quarter on the Timeline sheet | E21: =INDEX(Timeline!F:F,Inputs!C9) -> 4.0131007
B23: Change in cash sales and change in ROA need the year t−2; when it is missing both are set to 0, as in the Python engine.

Sheet Timeline
B2: Timeline
B3: Super Micro, trailing twelve months at each quarter end, as first filed · $ millions · scores by formula
B5: Quarter end | C5: Filed | D5: Complete | E5: M-score | F5: F-score | G5: Accruals / assets | H5: CFO / net income | I5: Receivable days | J5: Inventory days | K5: M flag | L5: F flag | M5: DSRI | N5: GMI | O5: AQI | P5: SGI | Q5: DEPI | R5: SGAI | S5: TATA | T5: LVGI | U5: RSST accruals | V5: Change in receivables | W5: Change in inventory | X5: Soft assets | Y5: Change in cash sales | Z5: Change in ROA | AA5: Securities issued (0/1) | AB5: F-score logit | AD5: t: Sales | AE5: t: Cost of sales | AF5: t: SG&A | AG5: t: Depreciation | AH5: t: Net income | AI5: t: Operating cash flow | AJ5: t: Debt/equity issued | AK5: t: Receivables | AL5: t: Inventory | AM5: t: Current assets | AN5: t: Total assets | AO5: t: Net PP&E | AP5: t: Cash | AQ5: t: Short-term investments | AR5: t: Long-term investments | AS5: t: Current liabilities | AT5: t: Total liabilities | AU5: t: Long-term debt | AV5: t: Current debt | AW5: t−1: Sales | AX5: t−1: Cost of sales | AY5: t−1: SG&A | AZ5: t−1: Depreciation | BA5: t−1: Net income | BB5: t−1: Operating cash flow | BC5: t−1: Debt/equity issued | BD5: t−1: Receivables | BE5: t−1: Inventory | BF5: t−1: Current assets | BG5: t−1: Total assets | BH5: t−1: Net PP&E | BI5: t−1: Cash | BJ5: t−1: Short-term investments | BK5: t−1: Long-term investments | BL5: t−1: Current liabilities | BM5: t−1: Total liabilities | BN5: t−1: Long-term debt | BO5: t−1: Current debt | BP5: t−2: Receivables | BQ5: t−2: Sales | BR5: t−2: Total assets | BS5: t−2: Net income
B6: 41455 | C6: 41528 | D6: yes | E6: =Inputs!$C$13+Inputs!$C$14*M6+Inputs!$C$15*N6+Inputs!$C$16*O6+Inputs!$C$17*P6+Inputs!$C$18*Q6+Inputs!$C$19*R6+Inputs!$C$20*S6+Inputs!$C$21*T6 -> -1.8222756 | F6: =EXP(AB6)/(1+EXP(AB6))/Inputs!$C$32 -> 0.50365119 | G6: =IFERROR((AH6-AI6)/((AN6+BG6)/2),"n/a") -> 0.012602345 | H6: =IFERROR(AI6/AH6,"n/a") -> 0.63832887 | I6: =IFERROR(AK6/AD6*365,"n/a") -> 46.887088 | J6: =IFERROR(N(AL6)/AE6*365,"n/a") -> 92.53996 | K6: =IF(E6>Inputs!$C$7,1,0) -> 0 | L6: =IF(F6>Inputs!$C$8,1,0) -> 0 | M6: =IFERROR((AK6/AD6)/(BD6/AW6),1) -> 1.2766875 | N6: =IFERROR(((AW6-AX6)/AW6)/((AD6-AE6)/AD6),1) -> 1.1850811 | O6: =IFERROR((1-(AM6+AO6)/AN6)/(1-(BF6+BH6)/BG6),1) -> 1.2541196 | P6: =IFERROR(AD6/AW6,1) -> 1.1466523 | Q6: =IFERROR((AZ6/(AZ6+BH6))/(AG6/(AG6+AO6)),1) -> 0.89607148 | R6: =IFERROR((AF6/AD6)/(AY6/AW6),1) -> 0.91172632 | S6: =IFERROR((AH6-AI6)/AN6,0) -> 0.012172265 | T6: =IFERROR(((AS6+N(AU6))/AN6)/((BL6+N(BN6))/BG6),1) -> 0.96395872 | U6: =IFERROR((((AM6-AP6-N(AQ6))-(AS6-N(AV6))+(AN6-AM6-N(AR6))-(AT6-AS6-N(AU6))+(N(AQ6)+N(AR6))-(N(AU6)+N(AV6)))-((BF6-BI6-N(BJ6))-(BL6-N(BO6))+(BG6-BF6-N(BK6))-(BM6-BL6-N(BN6))+(N(BJ6)+N(BK6))-(N(BN6)+N(BO6))))/((AN6+BG6)/2),0) -> 0.037926574 | V6: =IFERROR((AK6-BD6)/((AN6+BG6)/2),0) -> 0.077497216 | W6: =IFERROR((N(AL6)-N(BE6))/((AN6+BG6)/2),0) -> -0.03672791 | X6: =IFERROR((AN6-N(AO6)-AP6)/AN6,0) -> 0.70115001 | Y6: =IF(COUNT(BP6,BQ6,BR6,BS6)=4,IFERROR((AD6-(AK6-BD6))/(AW6-(BD6-BP6))-1,0),0) -> 0.11874226 | Z6: =IF(COUNT(BP6,BQ6,BR6,BS6)=4,IFERROR(AH6/((AN6+BG6)/2)-BA6/((BG6+BR6)/2),0),0) -> -0.021817187 | AA6: =IF(N(AJ6)>0,1,0) -> 0 | AB6: =Inputs!$C$24+Inputs!$C$25*U6+Inputs!$C$26*V6+Inputs!$C$27*W6+Inputs!$C$28*X6+Inputs!$C$29*Y6+Inputs!$C$30*Z6+Inputs!$C$31*AA6 -> -6.2834285 | AD6: 1162.561 | AE6: 1002.508 | AF6: 57.687 | AG6: 7.835 | AH6: 21.279 | AI6: 13.583 | AJ6: n/a | AK6: 149.34 | AL6: 254.17 | AM6: 523.192 | AN6: 632.257 | AO6: 95.912 | AP6: 93.038 | AQ6: n/a | AR6: 2.637 | AS6: 241.664 | AT6: 258.533 | AU6: 6.533 | AV6: 28.638 | AW6: 1013.874 | AX6: 848.457 | AY6: 55.18 | AZ6: 7.071 | BA6: 29.853 | BB6: 16.467 | BC6: n/a | BD6: 102.014 | BE6: 276.599 | BF6: 481.912 | BG6: 589.103 | BH6: 97.419 | BI6: 80.826 | BJ6: n/a | BK6: 2.923 | BL6: 220.508 | BM6: 250.752 | BN6: 19.395 | BO6: 13.362 | BP6: 85.005 | BQ6: 942.582 | BR6: 464.62 | BS6: 40.213
B7: 41547 | C7: 41585 | D7: yes | E7: =Inputs!$C$13+Inputs!$C$14*M7+Inputs!$C$15*N7+Inputs!$C$16*O7+Inputs!$C$17*P7+Inputs!$C$18*Q7+Inputs!$C$19*R7+Inputs!$C$20*S7+Inputs!$C$21*T7 -> -2.40065 | F7: =EXP(AB7)/(1+EXP(AB7))/Inputs!$C$32 -> 0.41430176 | G7: =IFERROR((AH7-AI7)/((AN7+BG7)/2),"n/a") -> -0.050509671 | H7: =IFERROR(AI7/AH7,"n/a") -> 2.0814132 | I7: =IFERROR(AK7/AD7*365,"n/a") -> 40.745826 | J7: =IFERROR(N(AL7)/AE7*365,"n/a") -> 90.203636 | K7: =IF(E7>Inputs!$C$7,1,0) -> 0 | L7: =IF(F7>Inputs!$C$8,1,0) -> 0 | M7: =IFERROR((AK7/AD7)/(BD7/AW7),1) -> 1.0260833 | N7: =IFERROR(((AW7-AX7)/AW7)/((AD7-AE7)/AD7),1) -> 1.0840463 | O7: =IFERROR((1-(AM7+AO7)/AN7)/(1-(BF7+BH7)/BG7),1) -> 1.160467 | P7: =IFERROR(AD7/AW7,1) -> 1.1583627 | Q7: =IFERROR((AZ7/(AZ7+BH7))/(AG7/(AG7+AO7)),1) -> 1.0243422 | R7: =IFERROR((AF7/AD7)/(AY7/AW7),1) -> 0.8496544 | S7: =IFERROR((AH7-AI7)/AN7,0) -> -0.047758804 | T7: =IFERROR(((AS7+N(AU7))/AN7)/((BL7+N(BN7))/BG7),1) -> 1.0009378 | U7: =IFERROR((((AM7-AP7-N(AQ7))-(AS7-N(AV7))+(AN7-AM7-N(AR7))-(AT7-AS7-N(AU7))+(N(AQ7)+N(AR7))-(N(AU7)+N(AV7)))-((BF7-BI7-N(BJ7))-(BL7-N(BO7))+(BG7-BF7-N(BK7))-(BM7-BL7-N(BN7))+(N(BJ7)+N(BK7))-(N(BN7)+N(BO7))))/((AN7+BG7)/2),0) -> -0.016045325 | V7: =IFERROR((AK7-BD7)/((AN7+BG7)/2),0) -> 0.035379226 | W7: =IFERROR((N(AL7)-N(BE7))/((AN7+BG7)/2),0) -> -0.014707937 | X7: =IFERROR((AN7-N(AO7)-AP7)/AN7,0) -> 0.6724987 | Y7: =IF(COUNT(BP7,BQ7,BR7,BS7)=4,IFERROR((AD7-(AK7-BD7))/(AW7-(BD7-BP7))-1,0),0) -> 0.16593738 | Z7: =IF(COUNT(BP7,BQ7,BR7,BS7)=4,IFERROR(AH7/((AN7+BG7)/2)-BA7/((BG7+BR7)/2),0),0) -> 0.004497004 | AA7: =IF(N(AJ7)>0,1,0) -> 0 | AB7: =Inputs!$C$24+Inputs!$C$25*U7+Inputs!$C$26*V7+Inputs!$C$27*W7+Inputs!$C$28*X7+Inputs!$C$29*Y7+Inputs!$C$30*Z7+Inputs!$C$31*AA7 -> -6.4790491 | AD7: 1200.87 | AE7: 1029.04 | AF7: 57.088 | AG7: 7.273 | AH7: 28.079 | AI7: 58.444 | AJ7: n/a | AK7: 134.056 | AL7: 254.31 | AM7: 524.222 | AN7: 635.799 | AO7: 96.767 | AP7: 111.458 | AQ7: n/a | AR7: 2.637 | AS7: 218.283 | AT7: 249.835 | AU7: 21.05 | AV7: 13.699 | AW7: 1036.696 | AX7: 875.89 | AY7: 58.004 | AZ7: 7.491 | BA7: 22.26 | BB7: -35.224 | BC7: n/a | BD7: 112.787 | BE7: 263.152 | BF7: 458.052 | BG7: 566.545 | BH7: 97.121 | BI7: 58.323 | BJ7: n/a | BK7: 2.923 | BL7: 204.431 | BM7: 224.07 | BN7: 8.633 | BO7: 18.124 | BP7: 87.81 | BQ7: 983.289 | BR7: 488.179 | BS7: 41.488
B8: 41639 | C8: 41677 | D8: yes | E8: =Inputs!$C$13+Inputs!$C$14*M8+Inputs!$C$15*N8+Inputs!$C$16*O8+Inputs!$C$17*P8+Inputs!$C$18*Q8+Inputs!$C$19*R8+Inputs!$C$20*S8+Inputs!$C$21*T8 -> -2.0828242 | F8: =EXP(AB8)/(1+EXP(AB8))/Inputs!$C$32 -> 0.54917185 | G8: =IFERROR((AH8-AI8)/((AN8+BG8)/2),"n/a") -> 0.01566976 | H8: =IFERROR(AI8/AH8,"n/a") -> 0.72260274 | I8: =IFERROR(AK8/AD8*365,"n/a") -> 46.477379 | J8: =IFERROR(N(AL8)/AE8*365,"n/a") -> 98.418691 | K8: =IF(E8>Inputs!$C$7,1,0) -> 0 | L8: =IF(F8>Inputs!$C$8,1,0) -> 0 | M8: =IFERROR((AK8/AD8)/(BD8/AW8),1) -> 1.1546485 | N8: =IFERROR(((AW8-AX8)/AW8)/((AD8-AE8)/AD8),1) -> 0.99485996 | O8: =IFERROR((1-(AM8+AO8)/AN8)/(1-(BF8+BH8)/BG8),1) -> 0.94777637 | P8: =IFERROR(AD8/AW8,1) -> 1.1738686 | Q8: =IFERROR((AZ8/(AZ8+BH8))/(AG8/(AG8+AO8)),1) -> 1.5014497 | R8: =IFERROR((AF8/AD8)/(AY8/AW8),1) -> 0.84318379 | S8: =IFERROR((AH8-AI8)/AN8,0) -> 0.014286097 | T8: =IFERROR(((AS8+N(AU8))/AN8)/((BL8+N(BN8))/BG8),1) -> 1.0852083 | U8: =IFERROR((((AM8-AP8-N(AQ8))-(AS8-N(AV8))+(AN8-AM8-N(AR8))-(AT8-AS8-N(AU8))+(N(AQ8)+N(AR8))-(N(AU8)+N(AV8)))-((BF8-BI8-N(BJ8))-(BL8-N(BO8))+(BG8-BF8-N(BK8))-(BM8-BL8-N(BN8))+(N(BJ8)+N(BK8))-(N(BN8)+N(BO8))))/((AN8+BG8)/2),0) -> 0.081841804 | V8: =IFERROR((AK8-BD8)/((AN8+BG8)/2),0) -> 0.065405967 | W8: =IFERROR((N(AL8)-N(BE8))/((AN8+BG8)/2),0) -> 0.073249359 | X8: =IFERROR((AN8-N(AO8)-AP8)/AN8,0) -> 0.69247147 | Y8: =IF(COUNT(BP8,BQ8,BR8,BS8)=4,IFERROR((AD8-(AK8-BD8))/(AW8-(BD8-BP8))-1,0),0) -> 0.17704164 | Z8: =IF(COUNT(BP8,BQ8,BR8,BS8)=4,IFERROR(AH8/((AN8+BG8)/2)-BA8/((BG8+BR8)/2),0),0) -> 0.022526519 | AA8: =IF(N(AJ8)>0,1,0) -> 0 | AB8: =Inputs!$C$24+Inputs!$C$25*U8+Inputs!$C$26*V8+Inputs!$C$27*W8+Inputs!$C$28*X8+Inputs!$C$29*Y8+Inputs!$C$30*Z8+Inputs!$C$31*AA8 -> -6.1967323 | AD8: 1265.745 | AE8: 1078.945 | AF8: 57.858 | AG8: 6.781 | AH8: 36.5 | AI8: 26.375 | AJ8: n/a | AK8: 161.174 | AL8: 290.927 | AM8: 567.583 | AN8: 708.731 | AO8: 128.072 | AP8: 89.883 | AQ8: n/a | AR8: 2.637 | AS8: 286.642 | AT8: 302.944 | AU8: 5.133 | AV8: 37.208 | AW8: 1078.268 | AX8: 919.954 | AY8: 58.455 | AZ8: 7.898 | BA8: 18.4 | BB8: -14.82 | BC8: n/a | BD8: 118.912 | BE8: 243.597 | BF8: 475.495 | BG8: 583.567 | BH8: 96.712 | BI8: 88.398 | BJ8: n/a | BK8: 2.65 | BL8: 213.45 | BM8: 232.147 | BN8: 7.933 | BO8: 29.195 | BP8: 80.1 | BQ8: 992.391 | BR8: 499.997 | BS8: 38.693
B9: 41729 | C9: 41766 | D9: yes | E9: =Inputs!$C$13+Inputs!$C$14*M9+Inputs!$C$15*N9+Inputs!$C$16*O9+Inputs!$C$17*P9+Inputs!$C$18*Q9+Inputs!$C$19*R9+Inputs!$C$20*S9+Inputs!$C$21*T9 -> -1.9335395 | F9: =EXP(AB9)/(1+EXP(AB9))/Inputs!$C$32 -> 0.5751915 | G9: =IFERROR((AH9-AI9)/((AN9+BG9)/2),"n/a") -> 0.049383443 | H9: =IFERROR(AI9/AH9,"n/a") -> 0.27127775 | I9: =IFERROR(AK9/AD9*365,"n/a") -> 48.800499 | J9: =IFERROR(N(AL9)/AE9*365,"n/a") -> 93.148794 | K9: =IF(E9>Inputs!$C$7,1,0) -> 0 | L9: =IF(F9>Inputs!$C$8,1,0) -> 0 | M9: =IFERROR((AK9/AD9)/(BD9/AW9),1) -> 1.2197727 | N9: =IFERROR(((AW9-AX9)/AW9)/((AD9-AE9)/AD9),1) -> 0.93031852 | O9: =IFERROR((1-(AM9+AO9)/AN9)/(1-(BF9+BH9)/BG9),1) -> 0.70809971 | P9: =IFERROR(AD9/AW9,1) -> 1.2198161 | Q9: =IFERROR((AZ9/(AZ9+BH9))/(AG9/(AG9+AO9)),1) -> 1.5740089 | R9: =IFERROR((AF9/AD9)/(AY9/AW9),1) -> 0.80470568 | S9: =IFERROR((AH9-AI9)/AN9,0) -> 0.044695759 | T9: =IFERROR(((AS9+N(AU9))/AN9)/((BL9+N(BN9))/BG9),1) -> 1.017798 | U9: =IFERROR((((AM9-AP9-N(AQ9))-(AS9-N(AV9))+(AN9-AM9-N(AR9))-(AT9-AS9-N(AU9))+(N(AQ9)+N(AR9))-(N(AU9)+N(AV9)))-((BF9-BI9-N(BJ9))-(BL9-N(BO9))+(BG9-BF9-N(BK9))-(BM9-BL9-N(BN9))+(N(BJ9)+N(BK9))-(N(BN9)+N(BO9))))/((AN9+BG9)/2),0) -> 0.10692238 | V9: =IFERROR((AK9-BD9)/((AN9+BG9)/2),0) -> 0.087868847 | W9: =IFERROR((N(AL9)-N(BE9))/((AN9+BG9)/2),0) -> 0.055569254 | X9: =IFERROR((AN9-N(AO9)-AP9)/AN9,0) -> 0.69326393 | Y9: =IF(COUNT(BP9,BQ9,BR9,BS9)=4,IFERROR((AD9-(AK9-BD9))/(AW9-(BD9-BP9))-1,0),0) -> 0.18909264 | Z9: =IF(COUNT(BP9,BQ9,BR9,BS9)=4,IFERROR(AH9/((AN9+BG9)/2)-BA9/((BG9+BR9)/2),0),0) -> 0.036001943 | AA9: =IF(N(AJ9)>0,1,0) -> 0 | AB9: =Inputs!$C$24+Inputs!$C$25*U9+Inputs!$C$26*V9+Inputs!$C$27*W9+Inputs!$C$28*X9+Inputs!$C$29*Y9+Inputs!$C$30*Z9+Inputs!$C$31*AA9 -> -6.1503442 | AD9: 1361.466 | AE9: 1156.295 | AF9: 58.233 | AG9: 6.525 | AH9: 46.034 | AI9: 12.488 | AJ9: n/a | AK9: 182.028 | AL9: 295.089 | AM9: 610.845 | AN9: 750.541 | AO9: 128.504 | AP9: 101.714 | AQ9: n/a | AR9: 2.637 | AS9: 292.53 | AT9: 308.002 | AU9: 4.433 | AV9: 42.13 | AW9: 1116.124 | AX9: 959.646 | AY9: 59.325 | AZ9: 7.857 | BA9: 18.363 | BB9: 11.008 | BC9: n/a | BD9: 122.339 | BE9: 257.341 | BF9: 499.805 | BG9: 608.052 | BH9: 95.442 | BI9: 93.974 | BJ9: n/a | BK9: 2.65 | BL9: 229.145 | BM9: 245.885 | BN9: 7.233 | BO9: 28.745 | BP9: 100.98 | BQ9: 998.281 | BR9: 548.118 | BS9: 35.074
B10: 41820 | C10: 41897 | D10: yes | E10: =Inputs!$C$13+Inputs!$C$14*M10+Inputs!$C$15*N10+Inputs!$C$16*O10+Inputs!$C$17*P10+Inputs!$C$18*Q10+Inputs!$C$19*R10+Inputs!$C$20*S10+Inputs!$C$21*T10 -> -1.9253139 | F10: =EXP(AB10)/(1+EXP(AB10))/Inputs!$C$32 -> 1.7794389 | G10: =IFERROR((AH10-AI10)/((AN10+BG10)/2),"n/a") -> 0.066666107 | H10: =IFERROR(AI10/AH10,"n/a") -> 0.12072308 | I10: =IFERROR(AK10/AD10*365,"n/a") -> 52.923435 | J10: =IFERROR(N(AL10)/AE10*365,"n/a") -> 92.844083 | K10: =IF(E10>Inputs!$C$7,1,0) -> 0 | L10: =IF(F10>Inputs!$C$8,1,0) -> 0 | M10: =IFERROR((AK10/AD10)/(BD10/AW10),1) -> 1.1287422 | N10: =IFERROR(((AW10-AX10)/AW10)/((AD10-AE10)/AD10),1) -> 0.8955808 | O10: =IFERROR((1-(AM10+AO10)/AN10)/(1-(BF10+BH10)/BG10),1) -> 0.70354317 | P10: =IFERROR(AD10/AW10,1) -> 1.262043 | Q10: =IFERROR((AZ10/(AZ10+BH10))/(AG10/(AG10+AO10)),1) -> 1.6251926 | R10: =IFERROR((AF10/AD10)/(AY10/AW10),1) -> 0.83827042 | S10: =IFERROR((AH10-AI10)/AN10,0) -> 0.059798449 | T10: =IFERROR(((AS10+N(AU10))/AN10)/((BL10+N(BN10))/BG10),1) -> 1.0064489 | U10: =IFERROR((((AM10-AP10-N(AQ10))-(AS10-N(AV10))+(AN10-AM10-N(AR10))-(AT10-AS10-N(AU10))+(N(AQ10)+N(AR10))-(N(AU10)+N(AV10)))-((BF10-BI10-N(BJ10))-(BL10-N(BO10))+(BG10-BF10-N(BK10))-(BM10-BL10-N(BN10))+(N(BJ10)+N(BK10))-(N(BN10)+N(BO10))))/((AN10+BG10)/2),0) -> 0.12834125 | V10: =IFERROR((AK10-BD10)/((AN10+BG10)/2),0) -> 0.088756543 | W10: =IFERROR((N(AL10)-N(BE10))/((AN10+BG10)/2),0) -> 0.086333161 | X10: =IFERROR((AN10-N(AO10)-AP10)/AN10,0) -> 0.7143616 | Y10: =IF(COUNT(BP10,BQ10,BR10,BS10)=4,IFERROR((AD10-(AK10-BD10))/(AW10-(BD10-BP10))-1,0),0) -> 0.25875174 | Z10: =IF(COUNT(BP10,BQ10,BR10,BS10)=4,IFERROR(AH10/((AN10+BG10)/2)-BA10/((BG10+BR10)/2),0),0) -> 0.040974476 | AA10: =IF(N(AJ10)>0,1,0) -> 1 | AB10: =Inputs!$C$24+Inputs!$C$25*U10+Inputs!$C$26*V10+Inputs!$C$27*W10+Inputs!$C$28*X10+Inputs!$C$29*Y10+Inputs!$C$30*Z10+Inputs!$C$31*AA10 -> -5.0165187 | AD10: 1467.202 | AE10: 1241.657 | AF10: 61.029 | AG10: 6.364 | AH10: 54.157 | AI10: 6.538 | AJ10: 17.354 | AK10: 212.738 | AL10: 315.837 | AM10: 654.081 | AN10: 796.325 | AO10: 130.589 | AP10: 96.872 | AQ10: n/a | AR10: 2.647 | AS10: 310.886 | AT10: 327.094 | AU10: 3.733 | AV10: 42.554 | AW10: 1162.561 | AX10: 1002.508 | AY10: 57.687 | AZ10: 7.835 | BA10: 21.279 | BB10: 13.583 | BC10: 20.641 | BD10: 149.34 | BE10: 254.17 | BF10: 523.192 | BG10: 632.257 | BH10: 95.912 | BI10: 93.038 | BJ10: n/a | BK10: 2.637 | BL10: 241.664 | BM10: 258.533 | BN10: 6.533 | BO10: 28.638 | BP10: 102.014 | BQ10: 1013.874 | BR10: 589.103 | BS10: 29.853
B11: 41912 | C11: 41949 | D11: yes | E11: =Inputs!$C$13+Inputs!$C$14*M11+Inputs!$C$15*N11+Inputs!$C$16*O11+Inputs!$C$17*P11+Inputs!$C$18*Q11+Inputs!$C$19*R11+Inputs!$C$20*S11+Inputs!$C$21*T11 -> -1.9654574 | F11: =EXP(AB11)/(1+EXP(AB11))/Inputs!$C$32 -> 0.64328928 | G11: =IFERROR((AH11-AI11)/((AN11+BG11)/2),"n/a") -> 0.071094767 | H11: =IFERROR(AI11/AH11,"n/a") -> 0.2269277 | I11: =IFERROR(AK11/AD11*365,"n/a") -> 44.298905 | J11: =IFERROR(N(AL11)/AE11*365,"n/a") -> 92.09956 | K11: =IF(E11>Inputs!$C$7,1,0) -> 0 | L11: =IF(F11>Inputs!$C$8,1,0) -> 0 | M11: =IFERROR((AK11/AD11)/(BD11/AW11),1) -> 1.087201 | N11: =IFERROR(((AW11-AX11)/AW11)/((AD11-AE11)/AD11),1) -> 0.92421923 | O11: =IFERROR((1-(AM11+AO11)/AN11)/(1-(BF11+BH11)/BG11),1) -> 0.52380486 | P11: =IFERROR(AD11/AW11,1) -> 1.3336231 | Q11: =IFERROR((AZ11/(AZ11+BH11))/(AG11/(AG11+AO11)),1) -> 1.4342584 | R11: =IFERROR((AF11/AD11)/(AY11/AW11),1) -> 0.82189431 | S11: =IFERROR((AH11-AI11)/AN11,0) -> 0.062834204 | T11: =IFERROR(((AS11+N(AU11))/AN11)/((BL11+N(BN11))/BG11),1) -> 1.0166797 | U11: =IFERROR((((AM11-AP11-N(AQ11))-(AS11-N(AV11))+(AN11-AM11-N(AR11))-(AT11-AS11-N(AU11))+(N(AQ11)+N(AR11))-(N(AU11)+N(AV11)))-((BF11-BI11-N(BJ11))-(BL11-N(BO11))+(BG11-BF11-N(BK11))-(BM11-BL11-N(BN11))+(N(BJ11)+N(BK11))-(N(BN11)+N(BO11))))/((AN11+BG11)/2),0) -> 0.14542434 | V11: =IFERROR((AK11-BD11)/((AN11+BG11)/2),0) -> 0.08239201 | W11: =IFERROR((N(AL11)-N(BE11))/((AN11+BG11)/2),0) -> 0.11916201 | X11: =IFERROR((AN11-N(AO11)-AP11)/AN11,0) -> 0.69746884 | Y11: =IF(COUNT(BP11,BQ11,BR11,BS11)=4,IFERROR((AD11-(AK11-BD11))/(AW11-(BD11-BP11))-1,0),0) -> 0.3065384 | Z11: =IF(COUNT(BP11,BQ11,BR11,BS11)=4,IFERROR(AH11/((AN11+BG11)/2)-BA11/((BG11+BR11)/2),0),0) -> 0.045256832 | AA11: =IF(N(AJ11)>0,1,0) -> 0 | AB11: =Inputs!$C$24+Inputs!$C$25*U11+Inputs!$C$26*V11+Inputs!$C$27*W11+Inputs!$C$28*X11+Inputs!$C$29*Y11+Inputs!$C$30*Z11+Inputs!$C$31*AA11 -> -6.0382002 | AD11: 1601.508 | AE11: 1353.562 | AF11: 62.574 | AG11: 6.818 | AH11: 67.321 | AI11: 15.277 | AJ11: n/a | AK11: 194.37 | AL11: 341.541 | AM11: 685.102 | AN11: 828.275 | AO11: 133.067 | AP11: 117.512 | AQ11: n/a | AR11: 2.647 | AS11: 313.954 | AT11: 329.801 | AU11: 3.033 | AV11: 34.446 | AW11: 1200.87 | AX11: 1029.04 | AY11: 57.088 | AZ11: 7.273 | BA11: 28.079 | BB11: 58.444 | BC11: n/a | BD11: 134.056 | BE11: 254.31 | BF11: 524.222 | BG11: 635.799 | BH11: 96.767 | BI11: 111.458 | BJ11: n/a | BK11: 2.637 | BL11: 218.283 | BM11: 249.835 | BN11: 21.05 | BO11: 13.699 | BP11: 112.787 | BQ11: 1036.696 | BR11: 566.545 | BS11: 22.26
B12: 42004 | C12: 42044 | D12: yes | E12: =Inputs!$C$13+Inputs!$C$14*M12+Inputs!$C$15*N12+Inputs!$C$16*O12+Inputs!$C$17*P12+Inputs!$C$18*Q12+Inputs!$C$19*R12+Inputs!$C$20*S12+Inputs!$C$21*T12 -> -1.6070338 | F12: =EXP(AB12)/(1+EXP(AB12))/Inputs!$C$32 -> 0.84437683 | G12: =IFERROR((AH12-AI12)/((AN12+BG12)/2),"n/a") -> 0.12869425 | H12: =IFERROR(AI12/AH12,"n/a") -> -0.24104754 | I12: =IFERROR(AK12/AD12*365,"n/a") -> 54.031759 | J12: =IFERROR(N(AL12)/AE12*365,"n/a") -> 101.54633 | K12: =IF(E12>Inputs!$C$7,1,0) -> 1 | L12: =IF(F12>Inputs!$C$8,1,0) -> 0 | M12: =IFERROR((AK12/AD12)/(BD12/AW12),1) -> 1.1625389 | N12: =IFERROR(((AW12-AX12)/AW12)/((AD12-AE12)/AD12),1) -> 0.93036329 | O12: =IFERROR((1-(AM12+AO12)/AN12)/(1-(BF12+BH12)/BG12),1) -> 0.61670387 | P12: =IFERROR(AD12/AW12,1) -> 1.3811313 | Q12: =IFERROR((AZ12/(AZ12+BH12))/(AG12/(AG12+AO12)),1) -> 1.0344482 | R12: =IFERROR((AF12/AD12)/(AY12/AW12),1) -> 0.80360915 | S12: =IFERROR((AH12-AI12)/AN12,0) -> 0.11312017 | T12: =IFERROR(((AS12+N(AU12))/AN12)/((BL12+N(BN12))/BG12),1) -> 0.9753788 | U12: =IFERROR((((AM12-AP12-N(AQ12))-(AS12-N(AV12))+(AN12-AM12-N(AR12))-(AT12-AS12-N(AU12))+(N(AQ12)+N(AR12))-(N(AU12)+N(AV12)))-((BF12-BI12-N(BJ12))-(BL12-N(BO12))+(BG12-BF12-N(BK12))-(BM12-BL12-N(BN12))+(N(BJ12)+N(BK12))-(N(BN12)+N(BO12))))/((AN12+BG12)/2),0) -> 0.17778256 | V12: =IFERROR((AK12-BD12)/((AN12+BG12)/2),0) -> 0.11876343 | W12: =IFERROR((N(AL12)-N(BE12))/((AN12+BG12)/2),0) -> 0.14391047 | X12: =IFERROR((AN12-N(AO12)-AP12)/AN12,0) -> 0.75844803 | Y12: =IF(COUNT(BP12,BQ12,BR12,BS12)=4,IFERROR((AD12-(AK12-BD12))/(AW12-(BD12-BP12))-1,0),0) -> 0.34905838 | Z12: =IF(COUNT(BP12,BQ12,BR12,BS12)=4,IFERROR(AH12/((AN12+BG12)/2)-BA12/((BG12+BR12)/2),0),0) -> 0.047209561 | AA12: =IF(N(AJ12)>0,1,0) -> 0 | AB12: =Inputs!$C$24+Inputs!$C$25*U12+Inputs!$C$26*V12+Inputs!$C$27*W12+Inputs!$C$28*X12+Inputs!$C$29*Y12+Inputs!$C$30*Z12+Inputs!$C$31*AA12 -> -5.7654498 | AD12: 1748.16 | AE12: 1470.854 | AF12: 64.216 | AG12: 7.289 | AH12: 85.228 | AI12: -20.544 | AJ12: n/a | AK12: 258.784 | AL12: 409.205 | AM12: 781.742 | AN12: 935.041 | AO12: 142.66 | AP12: 83.201 | AQ12: n/a | AR12: 2.647 | AS12: 373.133 | AT12: 389.819 | AU12: 2.333 | AV12: 33.459 | AW12: 1265.745 | AX12: 1078.945 | AY12: 57.858 | AZ12: 6.781 | BA12: 36.5 | BB12: 26.375 | BC12: n/a | BD12: 161.174 | BE12: 290.927 | BF12: 567.583 | BG12: 708.731 | BH12: 128.072 | BI12: 89.883 | BJ12: n/a | BK12: 2.637 | BL12: 286.642 | BM12: 302.944 | BN12: 5.133 | BO12: 37.208 | BP12: 118.912 | BQ12: 1078.268 | BR12: 583.567 | BS12: 18.4
B13: 42094 | C13: 42131 | D13: yes | E13: =Inputs!$C$13+Inputs!$C$14*M13+Inputs!$C$15*N13+Inputs!$C$16*O13+Inputs!$C$17*P13+Inputs!$C$18*Q13+Inputs!$C$19*R13+Inputs!$C$20*S13+Inputs!$C$21*T13 -> -1.8738848 | F13: =EXP(AB13)/(1+EXP(AB13))/Inputs!$C$32 -> 0.67138426 | G13: =IFERROR((AH13-AI13)/((AN13+BG13)/2),"n/a") -> 0.10351376 | H13: =IFERROR(AI13/AH13,"n/a") -> 0.034107513 | I13: =IFERROR(AK13/AD13*365,"n/a") -> 43.816889 | J13: =IFERROR(N(AL13)/AE13*365,"n/a") -> 101.42864 | K13: =IF(E13>Inputs!$C$7,1,0) -> 0 | L13: =IF(F13>Inputs!$C$8,1,0) -> 0 | M13: =IFERROR((AK13/AD13)/(BD13/AW13),1) -> 0.89787789 | N13: =IFERROR(((AW13-AX13)/AW13)/((AD13-AE13)/AD13),1) -> 0.93691287 | O13: =IFERROR((1-(AM13+AO13)/AN13)/(1-(BF13+BH13)/BG13),1) -> 0.86372671 | P13: =IFERROR(AD13/AW13,1) -> 1.3556196 | Q13: =IFERROR((AZ13/(AZ13+BH13))/(AG13/(AG13+AO13)),1) -> 1.0100902 | R13: =IFERROR((AF13/AD13)/(AY13/AW13),1) -> 0.8718322 | S13: =IFERROR((AH13-AI13)/AN13,0) -> 0.09218064 | T13: =IFERROR(((AS13+N(AU13))/AN13)/((BL13+N(BN13))/BG13),1) -> 0.94892709 | U13: =IFERROR((((AM13-AP13-N(AQ13))-(AS13-N(AV13))+(AN13-AM13-N(AR13))-(AT13-AS13-N(AU13))+(N(AQ13)+N(AR13))-(N(AU13)+N(AV13)))-((BF13-BI13-N(BJ13))-(BL13-N(BO13))+(BG13-BF13-N(BK13))-(BM13-BL13-N(BN13))+(N(BJ13)+N(BK13))-(N(BN13)+N(BO13))))/((AN13+BG13)/2),0) -> 0.1585543 | V13: =IFERROR((AK13-BD13)/((AN13+BG13)/2),0) -> 0.046196849 | W13: =IFERROR((N(AL13)-N(BE13))/((AN13+BG13)/2),0) -> 0.15809856 | X13: =IFERROR((AN13-N(AO13)-AP13)/AN13,0) -> 0.72675582 | Y13: =IF(COUNT(BP13,BQ13,BR13,BS13)=4,IFERROR((AD13-(AK13-BD13))/(AW13-(BD13-BP13))-1,0),0) -> 0.3874089 | Z13: =IF(COUNT(BP13,BQ13,BR13,BS13)=4,IFERROR(AH13/((AN13+BG13)/2)-BA13/((BG13+BR13)/2),0),0) -> 0.039401857 | AA13: =IF(N(AJ13)>0,1,0) -> 0 | AB13: =Inputs!$C$24+Inputs!$C$25*U13+Inputs!$C$26*V13+Inputs!$C$27*W13+Inputs!$C$28*X13+Inputs!$C$29*Y13+Inputs!$C$30*Z13+Inputs!$C$31*AA13 -> -5.9953489 | AD13: 1845.63 | AE13: 1548.768 | AF13: 68.824 | AG13: 7.704 | AH13: 91.71 | AI13: 3.128 | AJ13: n/a | AK13: 221.561 | AL13: 430.382 | AM13: 795.252 | AN13: 960.961 | AO13: 153.332 | AP13: 109.245 | AQ13: n/a | AR13: 2.647 | AS13: 359.167 | AT13: 375.208 | AU13: 1.633 | AV13: 44.836 | AW13: 1361.466 | AX13: 1156.295 | AY13: 58.233 | AZ13: 6.525 | BA13: 46.034 | BB13: 12.488 | BC13: n/a | BD13: 182.028 | BE13: 295.089 | BF13: 610.845 | BG13: 750.541 | BH13: 128.504 | BI13: 101.714 | BJ13: n/a | BK13: 2.637 | BL13: 292.53 | BM13: 308.002 | BN13: 4.433 | BO13: 42.13 | BP13: 122.339 | BQ13: 1116.124 | BR13: 608.052 | BS13: 18.363
B14: 42185 | C14: 42257 | D14: yes | E14: =Inputs!$C$13+Inputs!$C$14*M14+Inputs!$C$15*N14+Inputs!$C$16*O14+Inputs!$C$17*P14+Inputs!$C$18*Q14+Inputs!$C$19*R14+Inputs!$C$20*S14+Inputs!$C$21*T14 -> -1.5400437 | F14: =EXP(AB14)/(1+EXP(AB14))/Inputs!$C$32 -> 2.3889361 | G14: =IFERROR((AH14-AI14)/((AN14+BG14)/2),"n/a") -> 0.15534315 | H14: =IFERROR(AI14/AH14,"n/a") -> -0.4381964 | I14: =IFERROR(AK14/AD14*365,"n/a") -> 59.134929 | J14: =IFERROR(N(AL14)/AE14*365,"n/a") -> 101.24634 | K14: =IF(E14>Inputs!$C$7,1,0) -> 1 | L14: =IF(F14>Inputs!$C$8,1,0) -> 1 | M14: =IFERROR((AK14/AD14)/(BD14/AW14),1) -> 1.1173676 | N14: =IFERROR(((AW14-AX14)/AW14)/((AD14-AE14)/AD14),1) -> 0.95583954 | O14: =IFERROR((1-(AM14+AO14)/AN14)/(1-(BF14+BH14)/BG14),1) -> 0.7746501 | P14: =IFERROR(AD14/AW14,1) -> 1.3571103 | Q14: =IFERROR((AZ14/(AZ14+BH14))/(AG14/(AG14+AO14)),1) -> 0.97799816 | R14: =IFERROR((AF14/AD14)/(AY14/AW14),1) -> 0.88414961 | S14: =IFERROR((AH14-AI14)/AN14,0) -> 0.13442631 | T14: =IFERROR(((AS14+N(AU14))/AN14)/((BL14+N(BN14))/BG14),1) -> 1.0568287 | U14: =IFERROR((((AM14-AP14-N(AQ14))-(AS14-N(AV14))+(AN14-AM14-N(AR14))-(AT14-AS14-N(AU14))+(N(AQ14)+N(AR14))-(N(AU14)+N(AV14)))-((BF14-BI14-N(BJ14))-(BL14-N(BO14))+(BG14-BF14-N(BK14))-(BM14-BL14-N(BN14))+(N(BJ14)+N(BK14))-(N(BN14)+N(BO14))))/((AN14+BG14)/2),0) -> 0.16041702 | V14: =IFERROR((AK14-BD14)/((AN14+BG14)/2),0) -> 0.11648801 | W14: =IFERROR((N(AL14)-N(BE14))/((AN14+BG14)/2),0) -> 0.15657 | X14: =IFERROR((AN14-N(AO14)-AP14)/AN14,0) -> 0.76282082 | Y14: =IF(COUNT(BP14,BQ14,BR14,BS14)=4,IFERROR((AD14-(AK14-BD14))/(AW14-(BD14-BP14))-1,0),0) -> 0.34014364 | Z14: =IF(COUNT(BP14,BQ14,BR14,BS14)=4,IFERROR(AH14/((AN14+BG14)/2)-BA14/((BG14+BR14)/2),0),0) -> 0.032193235 | AA14: =IF(N(AJ14)>0,1,0) -> 1 | AB14: =Inputs!$C$24+Inputs!$C$25*U14+Inputs!$C$26*V14+Inputs!$C$27*W14+Inputs!$C$28*X14+Inputs!$C$29*Y14+Inputs!$C$30*Z14+Inputs!$C$31*AA14 -> -4.719696 | AD14: 1991.155 | AE14: 1670.924 | AF14: 73.228 | AG14: 8.133 | AH14: 101.863 | AI14: -44.636 | AJ14: 84.9 | AK14: 322.594 | AL14: 463.493 | AM14: 914.415 | AN14: 1089.809 | AO14: 163.038 | AP14: 95.442 | AQ14: n/a | AR14: 2.633 | AS14: 454.107 | AT14: 470.724 | AU14: 0.933 | AV14: 93.479 | AW14: 1467.202 | AX14: 1241.657 | AY14: 61.029 | AZ14: 6.364 | BA14: 54.157 | BB14: 6.538 | BC14: 17.354 | BD14: 212.738 | BE14: 315.837 | BF14: 654.081 | BG14: 796.325 | BH14: 130.589 | BI14: 96.872 | BJ14: n/a | BK14: 2.647 | BL14: 310.886 | BM14: 327.094 | BN14: 3.733 | BO14: 42.554 | BP14: 149.34 | BQ14: 1162.561 | BR14: 632.257 | BS14: 21.279
B15: 42277 | C15: 42324 | D15: yes | E15: =Inputs!$C$13+Inputs!$C$14*M15+Inputs!$C$15*N15+Inputs!$C$16*O15+Inputs!$C$17*P15+Inputs!$C$18*Q15+Inputs!$C$19*R15+Inputs!$C$20*S15+Inputs!$C$21*T15 -> -1.3881632 | F15: =EXP(AB15)/(1+EXP(AB15))/Inputs!$C$32 -> 2.1719029 | G15: =IFERROR((AH15-AI15)/((AN15+BG15)/2),"n/a") -> 0.15293714 | H15: =IFERROR(AI15/AH15,"n/a") -> -0.54251893 | I15: =IFERROR(AK15/AD15*365,"n/a") -> 52.447903 | J15: =IFERROR(N(AL15)/AE15*365,"n/a") -> 96.54891 | K15: =IF(E15>Inputs!$C$7,1,0) -> 1 | L15: =IF(F15>Inputs!$C$8,1,0) -> 1 | M15: =IFERROR((AK15/AD15)/(BD15/AW15),1) -> 1.1839549 | N15: =IFERROR(((AW15-AX15)/AW15)/((AD15-AE15)/AD15),1) -> 0.99019483 | O15: =IFERROR((1-(AM15+AO15)/AN15)/(1-(BF15+BH15)/BG15),1) -> 1.105623 | P15: =IFERROR(AD15/AW15,1) -> 1.2909402 | Q15: =IFERROR((AZ15/(AZ15+BH15))/(AG15/(AG15+AO15)),1) -> 0.96082416 | R15: =IFERROR((AF15/AD15)/(AY15/AW15),1) -> 0.9856363 | S15: =IFERROR((AH15-AI15)/AN15,0) -> 0.13500624 | T15: =IFERROR(((AS15+N(AU15))/AN15)/((BL15+N(BN15))/BG15),1) -> 1.0124601 | U15: =IFERROR((((AM15-AP15-N(AQ15))-(AS15-N(AV15))+(AN15-AM15-N(AR15))-(AT15-AS15-N(AU15))+(N(AQ15)+N(AR15))-(N(AU15)+N(AV15)))-((BF15-BI15-N(BJ15))-(BL15-N(BO15))+(BG15-BF15-N(BK15))-(BM15-BL15-N(BN15))+(N(BJ15)+N(BK15))-(N(BN15)+N(BO15))))/((AN15+BG15)/2),0) -> 0.15312873 | V15: =IFERROR((AK15-BD15)/((AN15+BG15)/2),0) -> 0.10753289 | W15: =IFERROR((N(AL15)-N(BE15))/((AN15+BG15)/2),0) -> 0.12545923 | X15: =IFERROR((AN15-N(AO15)-AP15)/AN15,0) -> 0.74117711 | Y15: =IF(COUNT(BP15,BQ15,BR15,BS15)=4,IFERROR((AD15-(AK15-BD15))/(AW15-(BD15-BP15))-1,0),0) -> 0.27481874 | Z15: =IF(COUNT(BP15,BQ15,BR15,BS15)=4,IFERROR(AH15/((AN15+BG15)/2)-BA15/((BG15+BR15)/2),0),0) -> 0.0071837254 | AA15: =IF(N(AJ15)>0,1,0) -> 1 | AB15: =Inputs!$C$24+Inputs!$C$25*U15+Inputs!$C$26*V15+Inputs!$C$27*W15+Inputs!$C$28*X15+Inputs!$C$29*Y15+Inputs!$C$30*Z15+Inputs!$C$31*AA15 -> -4.8157503 | AD15: 2067.451 | AE15: 1744.198 | AF15: 79.619 | AG15: 9.039 | AH15: 94.699 | AI15: -51.376 | AJ15: 89.6 | AK15: 297.078 | AL15: 461.371 | AM15: 898.242 | AN15: 1081.987 | AO15: 169.149 | AP15: 110.894 | AQ15: n/a | AR15: 2.633 | AS15: 419.011 | AT15: 443.873 | AU15: 0.233 | AV15: 94.574 | AW15: 1601.508 | AX15: 1353.562 | AY15: 62.574 | AZ15: 6.818 | BA15: 67.321 | BB15: 15.277 | BC15: n/a | BD15: 194.37 | BE15: 341.541 | BF15: 685.102 | BG15: 828.275 | BH15: 133.067 | BI15: 117.512 | BJ15: n/a | BK15: 2.647 | BL15: 313.954 | BM15: 329.801 | BN15: 3.033 | BO15: 34.446 | BP15: 134.056 | BQ15: 1200.87 | BR15: 635.799 | BS15: 28.079
B16: 42369 | C16: 42404 | D16: yes | E16: =Inputs!$C$13+Inputs!$C$14*M16+Inputs!$C$15*N16+Inputs!$C$16*O16+Inputs!$C$17*P16+Inputs!$C$18*Q16+Inputs!$C$19*R16+Inputs!$C$20*S16+Inputs!$C$21*T16 -> -1.9403519 | F16: =EXP(AB16)/(1+EXP(AB16))/Inputs!$C$32 -> 1.573808 | G16: =IFERROR((AH16-AI16)/((AN16+BG16)/2),"n/a") -> 0.044342215 | H16: =IFERROR(AI16/AH16,"n/a") -> 0.51935891 | I16: =IFERROR(AK16/AD16*365,"n/a") -> 52.044199 | J16: =IFERROR(N(AL16)/AE16*365,"n/a") -> 95.5657 | K16: =IF(E16>Inputs!$C$7,1,0) -> 0 | L16: =IF(F16>Inputs!$C$8,1,0) -> 0 | M16: =IFERROR((AK16/AD16)/(BD16/AW16),1) -> 0.96321496 | N16: =IFERROR(((AW16-AX16)/AW16)/((AD16-AE16)/AD16),1) -> 1.0126221 | O16: =IFERROR((1-(AM16+AO16)/AN16)/(1-(BF16+BH16)/BG16),1) -> 1.4589571 | P16: =IFERROR(AD16/AW16,1) -> 1.2604115 | Q16: =IFERROR((AZ16/(AZ16+BH16))/(AG16/(AG16+AO16)),1) -> 0.87068183 | R16: =IFERROR((AF16/AD16)/(AY16/AW16),1) -> 1.1179958 | S16: =IFERROR((AH16-AI16)/AN16,0) -> 0.039553494 | T16: =IFERROR(((AS16+N(AU16))/AN16)/((BL16+N(BN16))/BG16),1) -> 1.0023968 | U16: =IFERROR((((AM16-AP16-N(AQ16))-(AS16-N(AV16))+(AN16-AM16-N(AR16))-(AT16-AS16-N(AU16))+(N(AQ16)+N(AR16))-(N(AU16)+N(AV16)))-((BF16-BI16-N(BJ16))-(BL16-N(BO16))+(BG16-BF16-N(BK16))-(BM16-BL16-N(BN16))+(N(BJ16)+N(BK16))-(N(BN16)+N(BO16))))/((AN16+BG16)/2),0) -> 0.043460503 | V16: =IFERROR((AK16-BD16)/((AN16+BG16)/2),0) -> 0.052068005 | W16: =IFERROR((N(AL16)-N(BE16))/((AN16+BG16)/2),0) -> 0.072685776 | X16: =IFERROR((AN16-N(AO16)-AP16)/AN16,0) -> 0.71233182 | Y16: =IF(COUNT(BP16,BQ16,BR16,BS16)=4,IFERROR((AD16-(AK16-BD16))/(AW16-(BD16-BP16))-1,0),0) -> 0.30138984 | Z16: =IF(COUNT(BP16,BQ16,BR16,BS16)=4,IFERROR(AH16/((AN16+BG16)/2)-BA16/((BG16+BR16)/2),0),0) -> -0.011441682 | AA16: =IF(N(AJ16)>0,1,0) -> 1 | AB16: =Inputs!$C$24+Inputs!$C$25*U16+Inputs!$C$26*V16+Inputs!$C$27*W16+Inputs!$C$28*X16+Inputs!$C$29*Y16+Inputs!$C$30*Z16+Inputs!$C$31*AA16 -> -5.1400842 | AD16: 2203.401 | AE16: 1858.238 | AF16: 90.489 | AG16: 10.241 | AH16: 98.146 | AI16: 50.973 | AJ16: 94.1 | AK16: 314.176 | AL16: 486.531 | AM16: 999.648 | AN16: 1192.638 | AO16: 173.192 | AP16: 169.892 | AQ16: n/a | AR16: 2.633 | AS16: 480.052 | AT16: 514.49 | AU16: 0 | AV16: 94.233 | AW16: 1748.16 | AX16: 1470.854 | AY16: 64.216 | AZ16: 7.289 | BA16: 85.228 | BB16: -20.544 | BC16: n/a | BD16: 258.784 | BE16: 409.205 | BF16: 781.742 | BG16: 935.041 | BH16: 142.66 | BI16: 83.201 | BJ16: n/a | BK16: 2.647 | BL16: 373.133 | BM16: 389.819 | BN16: 2.333 | BO16: 33.459 | BP16: 161.174 | BQ16: 1265.745 | BR16: 708.731 | BS16: 36.5
B17: 42460 | C17: 42496 | D17: yes | E17: =Inputs!$C$13+Inputs!$C$14*M17+Inputs!$C$15*N17+Inputs!$C$16*O17+Inputs!$C$17*P17+Inputs!$C$18*Q17+Inputs!$C$19*R17+Inputs!$C$20*S17+Inputs!$C$21*T17 -> -1.9641548 | F17: =EXP(AB17)/(1+EXP(AB17))/Inputs!$C$32 -> 1.5161993 | G17: =IFERROR((AH17-AI17)/((AN17+BG17)/2),"n/a") -> 0.049135557 | H17: =IFERROR(AI17/AH17,"n/a") -> 0.42643212 | I17: =IFERROR(AK17/AD17*365,"n/a") -> 46.042855 | J17: =IFERROR(N(AL17)/AE17*365,"n/a") -> 91.235818 | K17: =IF(E17>Inputs!$C$7,1,0) -> 0 | L17: =IF(F17>Inputs!$C$8,1,0) -> 0 | M17: =IFERROR((AK17/AD17)/(BD17/AW17),1) -> 1.0508016 | N17: =IFERROR(((AW17-AX17)/AW17)/((AD17-AE17)/AD17),1) -> 1.0483586 | O17: =IFERROR((1-(AM17+AO17)/AN17)/(1-(BF17+BH17)/BG17),1) -> 1.1753479 | P17: =IFERROR(AD17/AW17,1) -> 1.2271674 | Q17: =IFERROR((AZ17/(AZ17+BH17))/(AG17/(AG17+AO17)),1) -> 0.77973348 | R17: =IFERROR((AF17/AD17)/(AY17/AW17),1) -> 1.1142741 | S17: =IFERROR((AH17-AI17)/AN17,0) -> 0.044556279 | T17: =IFERROR(((AS17+N(AU17))/AN17)/((BL17+N(BN17))/BG17),1) -> 0.97979353 | U17: =IFERROR((((AM17-AP17-N(AQ17))-(AS17-N(AV17))+(AN17-AM17-N(AR17))-(AT17-AS17-N(AU17))+(N(AQ17)+N(AR17))-(N(AU17)+N(AV17)))-((BF17-BI17-N(BJ17))-(BL17-N(BO17))+(BG17-BF17-N(BK17))-(BM17-BL17-N(BN17))+(N(BJ17)+N(BK17))-(N(BN17)+N(BO17))))/((AN17+BG17)/2),0) -> 0.052367005 | V17: =IFERROR((AK17-BD17)/((AN17+BG17)/2),0) -> 0.059889621 | W17: =IFERROR((N(AL17)-N(BE17))/((AN17+BG17)/2),0) -> 0.045651084 | X17: =IFERROR((AN17-N(AO17)-AP17)/AN17,0) -> 0.69856567 | Y17: =IF(COUNT(BP17,BQ17,BR17,BS17)=4,IFERROR((AD17-(AK17-BD17))/(AW17-(BD17-BP17))-1,0),0) -> 0.21851318 | Z17: =IF(COUNT(BP17,BQ17,BR17,BS17)=4,IFERROR(AH17/((AN17+BG17)/2)-BA17/((BG17+BR17)/2),0),0) -> -0.021502516 | AA17: =IF(N(AJ17)>0,1,0) -> 1 | AB17: =Inputs!$C$24+Inputs!$C$25*U17+Inputs!$C$26*V17+Inputs!$C$27*W17+Inputs!$C$28*X17+Inputs!$C$29*Y17+Inputs!$C$30*Z17+Inputs!$C$31*AA17 -> -5.17759 | AD17: 2264.897 | AE17: 1917.402 | AF17: 94.11 | AG17: 11.741 | AH17: 91.752 | AI17: 39.126 | AJ17: 72.6 | AK17: 285.705 | AL17: 479.276 | AM17: 983.611 | AN17: 1181.113 | AO17: 179.622 | AP17: 176.406 | AQ17: n/a | AR17: 2.633 | AS17: 434.497 | AT17: 472.112 | AU17: 0 | AV17: 93.795 | AW17: 1845.63 | AX17: 1548.768 | AY17: 68.824 | AZ17: 7.704 | BA17: 91.71 | BB17: 3.128 | BC17: n/a | BD17: 221.561 | BE17: 430.382 | BF17: 795.252 | BG17: 960.961 | BH17: 153.332 | BI17: 109.245 | BJ17: n/a | BK17: 2.647 | BL17: 359.167 | BM17: 375.208 | BN17: 1.633 | BO17: 44.836 | BP17: 182.028 | BQ17: 1361.466 | BR17: 750.541 | BS17: 46.034
B18: 42551 | C18: 42608 | D18: yes | E18: =Inputs!$C$13+Inputs!$C$14*M18+Inputs!$C$15*N18+Inputs!$C$16*O18+Inputs!$C$17*P18+Inputs!$C$18*Q18+Inputs!$C$19*R18+Inputs!$C$20*S18+Inputs!$C$21*T18 -> -1.8707052 | F18: =EXP(AB18)/(1+EXP(AB18))/Inputs!$C$32 -> 1.0831999 | G18: =IFERROR((AH18-AI18)/((AN18+BG18)/2),"n/a") -> -0.031469237 | H18: =IFERROR(AI18/AH18,"n/a") -> 1.4927452 | I18: =IFERROR(AK18/AD18*365,"n/a") -> 47.600989 | J18: =IFERROR(N(AL18)/AE18*365,"n/a") -> 86.981701 | K18: =IF(E18>Inputs!$C$7,1,0) -> 0 | L18: =IF(F18>Inputs!$C$8,1,0) -> 0 | M18: =IFERROR((AK18/AD18)/(BD18/AW18),1) -> 0.80495553 | N18: =IFERROR(((AW18-AX18)/AW18)/((AD18-AE18)/AD18),1) -> 1.0748011 | O18: =IFERROR((1-(AM18+AO18)/AN18)/(1-(BF18+BH18)/BG18),1) -> 3.0002344 | P18: =IFERROR(AD18/AW18,1) -> 1.1127074 | Q18: =IFERROR((AZ18/(AZ18+BH18))/(AG18/(AG18+AO18)),1) -> 0.71986655 | R18: =IFERROR((AF18/AD18)/(AY18/AW18),1) -> 1.2356326 | S18: =IFERROR((AH18-AI18)/AN18,0) -> -0.030446122 | T18: =IFERROR(((AS18+N(AU18))/AN18)/((BL18+N(BN18))/BG18),1) -> 0.82931936 | U18: =IFERROR((((AM18-AP18-N(AQ18))-(AS18-N(AV18))+(AN18-AM18-N(AR18))-(AT18-AS18-N(AU18))+(N(AQ18)+N(AR18))-(N(AU18)+N(AV18)))-((BF18-BI18-N(BJ18))-(BL18-N(BO18))+(BG18-BF18-N(BK18))-(BM18-BL18-N(BN18))+(N(BJ18)+N(BK18))-(N(BN18)+N(BO18))))/((AN18+BG18)/2),0) -> 0.01487269 | V18: =IFERROR((AK18-BD18)/((AN18+BG18)/2),0) -> -0.029842038 | W18: =IFERROR((N(AL18)-N(BE18))/((AN18+BG18)/2),0) -> -0.012869506 | X18: =IFERROR((AN18-N(AO18)-AP18)/AN18,0) -> 0.68349949 | Y18: =IF(COUNT(BP18,BQ18,BR18,BS18)=4,IFERROR((AD18-(AK18-BD18))/(AW18-(BD18-BP18))-1,0),0) -> 0.19557072 | Z18: =IF(COUNT(BP18,BQ18,BR18,BS18)=4,IFERROR(AH18/((AN18+BG18)/2)-BA18/((BG18+BR18)/2),0),0) -> -0.044147339 | AA18: =IF(N(AJ18)>0,1,0) -> 1 | AB18: =Inputs!$C$24+Inputs!$C$25*U18+Inputs!$C$26*V18+Inputs!$C$27*W18+Inputs!$C$28*X18+Inputs!$C$29*Y18+Inputs!$C$30*Z18+Inputs!$C$31*AA18 -> -5.515487 | AD18: 2215.573 | AE18: 1884.048 | AF18: 100.681 | AG18: 13.282 | AH18: 72.021 | AI18: 107.509 | AJ18: 34.2 | AK18: 288.941 | AL18: 448.98 | AM18: 938.002 | AN18: 1165.6 | AO18: 187.949 | AP18: 180.964 | AQ18: n/a | AR18: 2.643 | AS18: 363.618 | AT18: 444.221 | AU18: 40 | AV18: 53.589 | AW18: 1991.155 | AX18: 1670.924 | AY18: 73.228 | AZ18: 8.133 | BA18: 101.863 | BB18: -44.636 | BC18: 84.9 | BD18: 322.594 | BE18: 463.493 | BF18: 914.415 | BG18: 1089.809 | BH18: 163.038 | BI18: 95.442 | BJ18: n/a | BK18: 2.633 | BL18: 454.107 | BM18: 470.724 | BN18: 0.933 | BO18: 93.479 | BP18: 212.738 | BQ18: 1467.202 | BR18: 796.325 | BS18: 54.157
B19: 42643 | C19: 42681 | D19: yes | E19: =Inputs!$C$13+Inputs!$C$14*M19+Inputs!$C$15*N19+Inputs!$C$16*O19+Inputs!$C$17*P19+Inputs!$C$18*Q19+Inputs!$C$19*R19+Inputs!$C$20*S19+Inputs!$C$21*T19 -> -1.8604494 | F19: =EXP(AB19)/(1+EXP(AB19))/Inputs!$C$32 -> 1.4304573 | G19: =IFERROR((AH19-AI19)/((AN19+BG19)/2),"n/a") -> -0.0037401718 | H19: =IFERROR(AI19/AH19,"n/a") -> 1.0599271 | I19: =IFERROR(AK19/AD19*365,"n/a") -> 53.852405 | J19: =IFERROR(N(AL19)/AE19*365,"n/a") -> 96.78627 | K19: =IF(E19>Inputs!$C$7,1,0) -> 0 | L19: =IF(F19>Inputs!$C$8,1,0) -> 0 | M19: =IFERROR((AK19/AD19)/(BD19/AW19),1) -> 1.026779 | N19: =IFERROR(((AW19-AX19)/AW19)/((AD19-AE19)/AD19),1) -> 1.0250469 | O19: =IFERROR((1-(AM19+AO19)/AN19)/(1-(BF19+BH19)/BG19),1) -> 2.4512876 | P19: =IFERROR(AD19/AW19,1) -> 1.0761672 | Q19: =IFERROR((AZ19/(AZ19+BH19))/(AG19/(AG19+AO19)),1) -> 0.7262704 | R19: =IFERROR((AF19/AD19)/(AY19/AW19),1) -> 1.2243101 | S19: =IFERROR((AH19-AI19)/AN19,0) -> -0.0035278281 | T19: =IFERROR(((AS19+N(AU19))/AN19)/((BL19+N(BN19))/BG19),1) -> 0.95720261 | U19: =IFERROR((((AM19-AP19-N(AQ19))-(AS19-N(AV19))+(AN19-AM19-N(AR19))-(AT19-AS19-N(AU19))+(N(AQ19)+N(AR19))-(N(AU19)+N(AV19)))-((BF19-BI19-N(BJ19))-(BL19-N(BO19))+(BG19-BF19-N(BK19))-(BM19-BL19-N(BN19))+(N(BJ19)+N(BK19))-(N(BN19)+N(BO19))))/((AN19+BG19)/2),0) -> 0.042820885 | V19: =IFERROR((AK19-BD19)/((AN19+BG19)/2),0) -> 0.027090622 | W19: =IFERROR((N(AL19)-N(BE19))/((AN19+BG19)/2),0) -> 0.03354168 | X19: =IFERROR((AN19-N(AO19)-AP19)/AN19,0) -> 0.72345629 | Y19: =IF(COUNT(BP19,BQ19,BR19,BS19)=4,IFERROR((AD19-(AK19-BD19))/(AW19-(BD19-BP19))-1,0),0) -> 0.1165501 | Z19: =IF(COUNT(BP19,BQ19,BR19,BS19)=4,IFERROR(AH19/((AN19+BG19)/2)-BA19/((BG19+BR19)/2),0),0) -> -0.036735601 | AA19: =IF(N(AJ19)>0,1,0) -> 1 | AB19: =Inputs!$C$24+Inputs!$C$25*U19+Inputs!$C$26*V19+Inputs!$C$27*W19+Inputs!$C$28*X19+Inputs!$C$29*Y19+Inputs!$C$30*Z19+Inputs!$C$31*AA19 -> -5.2361215 | AD19: 2224.923 | AE19: 1885.549 | AF19: 104.903 | AG19: 14.331 | AH19: 71.854 | AI19: 76.16 | AJ19: 103.416 | AK19: 328.267 | AL19: 499.987 | AM19: 989.371 | AN19: 1220.581 | AO19: 190.848 | AP19: 146.696 | AQ19: n/a | AR19: 2.643 | AS19: 415.493 | AT19: 497.366 | AU19: 37.212 | AV19: 60.983 | AW19: 2067.451 | AX19: 1744.198 | AY19: 79.619 | AZ19: 9.039 | BA19: 94.699 | BB19: -51.376 | BC19: 89.6 | BD19: 297.078 | BE19: 461.371 | BF19: 898.242 | BG19: 1081.987 | BH19: 169.149 | BI19: 110.894 | BJ19: n/a | BK19: 2.633 | BL19: 419.011 | BM19: 443.873 | BN19: 0.233 | BO19: 94.574 | BP19: 194.37 | BQ19: 1601.508 | BR19: 828.275 | BS19: 67.321
B20: 42735 | C20: 42773 | D20: yes | E20: =Inputs!$C$13+Inputs!$C$14*M20+Inputs!$C$15*N20+Inputs!$C$16*O20+Inputs!$C$17*P20+Inputs!$C$18*Q20+Inputs!$C$19*R20+Inputs!$C$20*S20+Inputs!$C$21*T20 -> -1.6572464 | F20: =EXP(AB20)/(1+EXP(AB20))/Inputs!$C$32 -> 1.7550367 | G20: =IFERROR((AH20-AI20)/((AN20+BG20)/2),"n/a") -> 0.073505778 | H20: =IFERROR(AI20/AH20,"n/a") -> -0.57948649 | I20: =IFERROR(AK20/AD20*365,"n/a") -> 59.838352 | J20: =IFERROR(N(AL20)/AE20*365,"n/a") -> 114.42875 | K20: =IF(E20>Inputs!$C$7,1,0) -> 1 | L20: =IF(F20>Inputs!$C$8,1,0) -> 0 | M20: =IFERROR((AK20/AD20)/(BD20/AW20),1) -> 1.1497603 | N20: =IFERROR(((AW20-AX20)/AW20)/((AD20-AE20)/AD20),1) -> 1.074081 | O20: =IFERROR((1-(AM20+AO20)/AN20)/(1-(BF20+BH20)/BG20),1) -> 1.8912125 | P20: =IFERROR(AD20/AW20,1) -> 1.0156631 | Q20: =IFERROR((AZ20/(AZ20+BH20))/(AG20/(AG20+AO20)),1) -> 0.77474774 | R20: =IFERROR((AF20/AD20)/(AY20/AW20),1) -> 1.1480493 | S20: =IFERROR((AH20-AI20)/AN20,0) -> 0.069225162 | T20: =IFERROR(((AS20+N(AU20))/AN20)/((BL20+N(BN20))/BG20),1) -> 1.0021345 | U20: =IFERROR((((AM20-AP20-N(AQ20))-(AS20-N(AV20))+(AN20-AM20-N(AR20))-(AT20-AS20-N(AU20))+(N(AQ20)+N(AR20))-(N(AU20)+N(AV20)))-((BF20-BI20-N(BJ20))-(BL20-N(BO20))+(BG20-BF20-N(BK20))-(BM20-BL20-N(BN20))+(N(BJ20)+N(BK20))-(N(BN20)+N(BO20))))/((AN20+BG20)/2),0) -> 0.090740037 | V20: =IFERROR((AK20-BD20)/((AN20+BG20)/2),0) -> 0.041462438 | W20: =IFERROR((N(AL20)-N(BE20))/((AN20+BG20)/2),0) -> 0.088683002 | X20: =IFERROR((AN20-N(AO20)-AP20)/AN20,0) -> 0.76114341 | Y20: =IF(COUNT(BP20,BQ20,BR20,BS20)=4,IFERROR((AD20-(AK20-BD20))/(AW20-(BD20-BP20))-1,0),0) -> 0.017316035 | Z20: =IF(COUNT(BP20,BQ20,BR20,BS20)=4,IFERROR(AH20/((AN20+BG20)/2)-BA20/((BG20+BR20)/2),0),0) -> -0.045718628 | AA20: =IF(N(AJ20)>0,1,0) -> 1 | AB20: =Inputs!$C$24+Inputs!$C$25*U20+Inputs!$C$26*V20+Inputs!$C$27*W20+Inputs!$C$28*X20+Inputs!$C$29*Y20+Inputs!$C$30*Z20+Inputs!$C$31*AA20 -> -5.0304179 | AD20: 2237.913 | AE20: 1911.523 | AF20: 105.513 | AG20: 15.04 | AH20: 59.161 | AI20: -34.283 | AJ20: 149.916 | AK20: 366.885 | AL20: 599.269 | AM20: 1113.808 | AN20: 1349.856 | AO20: 193.67 | AP20: 128.752 | AQ20: n/a | AR20: 2.643 | AS20: 509.762 | AT20: 597.495 | AU20: 34.732 | AV20: 92.443 | AW20: 2203.401 | AX20: 1858.238 | AY20: 90.489 | AZ20: 10.241 | BA20: 98.146 | BB20: 50.973 | BC20: 94.1 | BD20: 314.176 | BE20: 486.531 | BF20: 999.648 | BG20: 1192.638 | BH20: 173.192 | BI20: 169.892 | BJ20: n/a | BK20: 2.633 | BL20: 480.052 | BM20: 514.49 | BN20: 0 | BO20: 94.233 | BP20: 258.784 | BQ20: 1748.16 | BR20: 935.041 | BS20: 85.228
B21: 42825 | C21: 42865 | D21: yes | E21: =Inputs!$C$13+Inputs!$C$14*M21+Inputs!$C$15*N21+Inputs!$C$16*O21+Inputs!$C$17*P21+Inputs!$C$18*Q21+Inputs!$C$19*R21+Inputs!$C$20*S21+Inputs!$C$21*T21 -> -1.1548226 | F21: =EXP(AB21)/(1+EXP(AB21))/Inputs!$C$32 -> 2.1340727 | G21: =IFERROR((AH21-AI21)/((AN21+BG21)/2),"n/a") -> 0.10423547 | H21: =IFERROR(AI21/AH21,"n/a") -> -1.2775966 | I21: =IFERROR(AK21/AD21*365,"n/a") -> 61.137667 | J21: =IFERROR(N(AL21)/AE21*365,"n/a") -> 117.17825 | K21: =IF(E21>Inputs!$C$7,1,0) -> 1 | L21: =IF(F21>Inputs!$C$8,1,0) -> 1 | M21: =IFERROR((AK21/AD21)/(BD21/AW21),1) -> 1.3278427 | N21: =IFERROR(((AW21-AX21)/AW21)/((AD21-AE21)/AD21),1) -> 1.0682092 | O21: =IFERROR((1-(AM21+AO21)/AN21)/(1-(BF21+BH21)/BG21),1) -> 2.4550086 | P21: =IFERROR(AD21/AW21,1) -> 1.031533 | Q21: =IFERROR((AZ21/(AZ21+BH21))/(AG21/(AG21+AO21)),1) -> 0.83482519 | R21: =IFERROR((AF21/AD21)/(AY21/AW21),1) -> 1.1547776 | S21: =IFERROR((AH21-AI21)/AN21,0) -> 0.09594747 | T21: =IFERROR(((AS21+N(AU21))/AN21)/((BL21+N(BN21))/BG21),1) -> 1.097017 | U21: =IFERROR((((AM21-AP21-N(AQ21))-(AS21-N(AV21))+(AN21-AM21-N(AR21))-(AT21-AS21-N(AU21))+(N(AQ21)+N(AR21))-(N(AU21)+N(AV21)))-((BF21-BI21-N(BJ21))-(BL21-N(BO21))+(BG21-BF21-N(BK21))-(BM21-BL21-N(BN21))+(N(BJ21)+N(BK21))-(N(BN21)+N(BO21))))/((AN21+BG21)/2),0) -> 0.10570362 | V21: =IFERROR((AK21-BD21)/((AN21+BG21)/2),0) -> 0.08170658 | W21: =IFERROR((N(AL21)-N(BE21))/((AN21+BG21)/2),0) -> 0.12611383 | X21: =IFERROR((AN21-N(AO21)-AP21)/AN21,0) -> 0.78402171 | Y21: =IF(COUNT(BP21,BQ21,BR21,BS21)=4,IFERROR((AD21-(AK21-BD21))/(AW21-(BD21-BP21))-1,0),0) -> 0.013601708 | Z21: =IF(COUNT(BP21,BQ21,BR21,BS21)=4,IFERROR(AH21/((AN21+BG21)/2)-BA21/((BG21+BR21)/2),0),0) -> -0.039900953 | AA21: =IF(N(AJ21)>0,1,0) -> 1 | AB21: =Inputs!$C$24+Inputs!$C$25*U21+Inputs!$C$26*V21+Inputs!$C$27*W21+Inputs!$C$28*X21+Inputs!$C$29*Y21+Inputs!$C$30*Z21+Inputs!$C$31*AA21 -> -4.8334629 | AD21: 2336.316 | AE21: 2000.752 | AF21: 112.103 | AG21: 15.512 | AH21: 59.165 | AI21: -75.589 | AJ21: 180.516 | AK21: 391.334 | AL21: 642.314 | AM21: 1156.707 | AN21: 1404.456 | AO21: 195.553 | AP21: 107.779 | AQ21: n/a | AR21: 2.643 | AS21: 534.532 | AT21: 627.43 | AU21: 32.251 | AV21: 113.26 | AW21: 2264.897 | AX21: 1917.402 | AY21: 94.11 | AZ21: 11.741 | BA21: 91.752 | BB21: 39.126 | BC21: 72.6 | BD21: 285.705 | BE21: 479.276 | BF21: 983.611 | BG21: 1181.113 | BH21: 179.622 | BI21: 176.406 | BJ21: n/a | BK21: 2.633 | BL21: 434.497 | BM21: 472.112 | BN21: 0 | BO21: 93.795 | BP21: 221.561 | BQ21: 1845.63 | BR21: 960.961 | BS21: 91.71
B22: 42916 | C22: 43602 | D22: yes | E22: =Inputs!$C$13+Inputs!$C$14*M22+Inputs!$C$15*N22+Inputs!$C$16*O22+Inputs!$C$17*P22+Inputs!$C$18*Q22+Inputs!$C$19*R22+Inputs!$C$20*S22+Inputs!$C$21*T22 -> -1.340136 | F22: =EXP(AB22)/(1+EXP(AB22))/Inputs!$C$32 -> 2.3906289 | G22: =IFERROR((AH22-AI22)/((AN22+BG22)/2),"n/a") -> 0.12047677 | H22: =IFERROR(AI22/AH22,"n/a") -> -1.438777 | I22: =IFERROR(AK22/AD22*365,"n/a") -> 47.591485 | J22: =IFERROR(N(AL22)/AE22*365,"n/a") -> 125.94261 | K22: =IF(E22>Inputs!$C$7,1,0) -> 1 | L22: =IF(F22>Inputs!$C$8,1,0) -> 1 | M22: =IFERROR((AK22/AD22)/(BD22/AW22),1) -> 1.6584369 | N22: =IFERROR(((AW22-AX22)/AW22)/((AD22-AE22)/AD22),1) -> 1.0547184 | O22: =IFERROR((1-(AM22+AO22)/AN22)/(1-(BF22+BH22)/BG22),1) -> 0.93313287 | P22: =IFERROR(AD22/AW22,1) -> 1.116811 | Q22: =IFERROR((AZ22/(AZ22+BH22))/(AG22/(AG22+AO22)),1) -> 0.85519179 | R22: =IFERROR((AF22/AD22)/(AY22/AW22),1) -> 1.0069303 | S22: =IFERROR((AH22-AI22)/AN22,0) -> 0.10760925 | T22: =IFERROR(((AS22+N(AU22))/AN22)/((BL22+N(BN22))/BG22),1) -> 1.1762356 | U22: =IFERROR((((AM22-AP22-N(AQ22))-(AS22-N(AV22))+(AN22-AM22-N(AR22))-(AT22-AS22-N(AU22))+(N(AQ22)+N(AR22))-(N(AU22)+N(AV22)))-((BF22-BI22-N(BJ22))-(BL22-N(BO22))+(BG22-BF22-N(BK22))-(BM22-BL22-N(BN22))+(N(BJ22)+N(BK22))-(N(BN22)+N(BO22))))/((AN22+BG22)/2),0) -> 0.10744573 | V22: =IFERROR((AK22-BD22)/((AN22+BG22)/2),0) -> 0.11015317 | W22: =IFERROR((N(AL22)-N(BE22))/((AN22+BG22)/2),0) -> 0.16246209 | X22: =IFERROR((AN22-N(AO22)-AP22)/AN22,0) -> 0.79791701 | Y22: =IF(COUNT(BP22,BQ22,BR22,BS22)=4,IFERROR((AD22-(AK22-BD22))/(AW22-(BD22-BP22))-1,0),0) -> -0.015520405 | Z22: =IF(COUNT(BP22,BQ22,BR22,BS22)=4,IFERROR(AH22/((AN22+BG22)/2)-BA22/((BG22+BR22)/2),0),0) -> -0.013792651 | AA22: =IF(N(AJ22)>0,1,0) -> 1 | AB22: =Inputs!$C$24+Inputs!$C$25*U22+Inputs!$C$26*V22+Inputs!$C$27*W22+Inputs!$C$28*X22+Inputs!$C$29*Y22+Inputs!$C$30*Z22+Inputs!$C$31*AA22 -> -4.7189813 | AD22: 2484.929 | AE22: 2134.971 | AF22: 111.091 | AG22: 16.357 | AH22: 66.854 | AI22: -96.188 | AJ22: 207.029 | AK22: 324.004 | AL22: 736.668 | AM22: 1261.166 | AN22: 1515.13 | AO22: 195.576 | AP22: 110.606 | AQ22: n/a | AR22: 2.625 | AS22: 672.53 | AT22: 741.284 | AU22: 0 | AV22: 161.447 | AW22: 2225.022 | AX22: 1894.521 | AY22: 98.787 | AZ22: 13.282 | BA22: 72.081 | BB22: 107.987 | BC22: 34.2 | BD22: 174.933 | BE22: 516.807 | BF22: 954.328 | BG22: 1191.483 | BH22: 187.949 | BI22: 178.82 | BJ22: n/a | BK22: 2.643 | BL22: 409.63 | BM22: 494.83 | BN22: 40 | BO22: 53.589 | BP22: 322.594 | BQ22: 1954.353 | BR22: 1089.809 | BS22: 92.555
B23: 43281 | C23: 43818 | D23: yes | E23: =Inputs!$C$13+Inputs!$C$14*M23+Inputs!$C$15*N23+Inputs!$C$16*O23+Inputs!$C$17*P23+Inputs!$C$18*Q23+Inputs!$C$19*R23+Inputs!$C$20*S23+Inputs!$C$21*T23 -> -2.4008944 | F23: =EXP(AB23)/(1+EXP(AB23))/Inputs!$C$32 -> 2.1260113 | G23: =IFERROR((AH23-AI23)/((AN23+BG23)/2),"n/a") -> -0.023248854 | H23: =IFERROR(AI23/AH23,"n/a") -> 1.8270768 | I23: =IFERROR(AK23/AD23*365,"n/a") -> 49.028072 | J23: =IFERROR(N(AL23)/AE23*365,"n/a") -> 106.27442 | K23: =IF(E23>Inputs!$C$7,1,0) -> 0 | L23: =IF(F23>Inputs!$C$8,1,0) -> 1 | M23: =IFERROR((AK23/AD23)/(BD23/AW23),1) -> 1.0301858 | N23: =IFERROR(((AW23-AX23)/AW23)/((AD23-AE23)/AD23),1) -> 1.1006327 | O23: =IFERROR((1-(AM23+AO23)/AN23)/(1-(BF23+BH23)/BG23),1) -> 0.61586061 | P23: =IFERROR(AD23/AW23,1) -> 1.3523493 | Q23: =IFERROR((AZ23/(AZ23+BH23))/(AG23/(AG23+AO23)),1) -> 0.77186058 | R23: =IFERROR((AF23/AD23)/(AY23/AW23),1) -> 1.1327408 | S23: =IFERROR((AH23-AI23)/AN23,0) -> -0.021577786 | T23: =IFERROR(((AS23+N(AU23))/AN23)/((BL23+N(BN23))/BG23),1) -> 1.0332501 | U23: =IFERROR((((AM23-AP23-N(AQ23))-(AS23-N(AV23))+(AN23-AM23-N(AR23))-(AT23-AS23-N(AU23))+(N(AQ23)+N(AR23))-(N(AU23)+N(AV23)))-((BF23-BI23-N(BJ23))-(BL23-N(BO23))+(BG23-BF23-N(BK23))-(BM23-BL23-N(BN23))+(N(BJ23)+N(BK23))-(N(BN23)+N(BO23))))/((AN23+BG23)/2),0) -> 0.039599529 | V23: =IFERROR((AK23-BD23)/((AN23+BG23)/2),0) -> 0.077566609 | W23: =IFERROR((N(AL23)-N(BE23))/((AN23+BG23)/2),0) -> 0.070987492 | X23: =IFERROR((AN23-N(AO23)-AP23)/AN23,0) -> 0.82367498 | Y23: =IF(COUNT(BP23,BQ23,BR23,BS23)=4,IFERROR((AD23-(AK23-BD23))/(AW23-(BD23-BP23))-1,0),0) -> 0.38411796 | Z23: =IF(COUNT(BP23,BQ23,BR23,BS23)=4,IFERROR(AH23/((AN23+BG23)/2)-BA23/((BG23+BR23)/2),0),0) -> -0.021290819 | AA23: =IF(N(AJ23)>0,1,0) -> 1 | AB23: =Inputs!$C$24+Inputs!$C$25*U23+Inputs!$C$26*V23+Inputs!$C$27*W23+Inputs!$C$28*X23+Inputs!$C$29*Y23+Inputs!$C$30*Z23+Inputs!$C$31*AA23 -> -4.8372775 | AD23: 3360.492 | AE23: 2930.498 | AF23: 170.176 | AG23: 21.846 | AH23: 46.165 | AI23: 84.347 | AJ23: 107.337 | AK23: 451.393 | AL23: 853.252 | AM23: 1530.878 | AN23: 1769.505 | AO23: 196.631 | AP23: 115.377 | AQ23: n/a | AR23: 1.571 | AS23: 811.557 | AT23: 925.853 | AU23: n/a | AV23: 116.181 | AW23: 2484.929 | AX23: 2134.971 | AY23: 111.091 | AZ23: 16.357 | BA23: 66.854 | BB23: -96.188 | BC23: 207.029 | BD23: 324.004 | BE23: 736.668 | BF23: 1261.166 | BG23: 1515.13 | BH23: 195.576 | BI23: 110.606 | BJ23: n/a | BK23: 2.625 | BL23: 672.53 | BM23: 741.284 | BN23: 0 | BO23: 161.447 | BP23: 174.933 | BQ23: 2225.022 | BR23: 1191.483 | BS23: 72.081
